<?xml version="1.0" ?>
<!-- =================================================================================== -->
<!-- |    This document was autogenerated by xacro from ./boxy_description.urdf.xacro  | -->
<!-- |    EDITING THIS FILE BY HAND IS NOT RECOMMENDED                                 | -->
<!-- =================================================================================== -->
<robot name="boxy_description" xmlns:controller="http://playerstage.sourceforge.net/gazebo/xmlschema/#controller" xmlns:interface="http://playerstage.sourceforge.net/gazebo/xmlschema/#interface" xmlns:sensor="http://playerstage.sourceforge.net/gazebo/xmlschema/#sensor" xmlns:xacro="http://ros.org/wiki/xacro">
  <material name="DarkGrey">
    <color rgba="0.3 0.3 0.3 1.0"/>
  </material>
  <material name="Black">
    <color rgba="0 0 0 1.0"/>
  </material>
  <material name="Orange">
    <color rgba="1.0 0.487 0 1.0"/>
  </material>
  <material name="Silver">
    <color rgba="1.0 1.0 1.0 1.0"/>
  </material>
  <material name="Grey">
    <color rgba="0.7 0.7 0.7 1.0"/>
  </material>
  <material name="Blue">
    <color rgba="0.0 0.0 0.8 1.0"/>
  </material>
  <material name="HandGray">
    <color rgba="0.953 0.996 0.694 1.0"/>
  </material>
  <material name="SickBlue">
    <color rgba="0.3058 0.5921 0.7294 1.0"/>
  </material>
  <!-- Property definitions e.g. constants -->
  <!--this is the diamiter of one of the aluminium (/2) pipes (20mm) = the diamiter of the piece that holds the slider (45mm) -->
  <!-- distance from the axis 0 to the first alu pipe 74 + distance between the pipes 150 + diamiter of the slider 200 /2   ( = center ) -->
  <!-- /Property definitions e.g. constants -->
  <link name="base_link">
    <inertial>
      <origin rpy="0 0 0" xyz="-0.25490068146997 -0.227666278193656 0.045962661102728"/>
      <mass value="70.4306942428661"/>
      <inertia ixx="7.99622647278776" ixy="-0.0894854703454988" ixz="0.576697407260801" iyy="11.5158519039036" iyz="0.0157078278260758" izz="7.49426546428967"/>
    </inertial>
    <visual>
      <origin rpy="0 0 0" xyz="0 0 0"/>
      <geometry>
        <mesh filename="package://iai_boxy_base/meshes/base_link.STL"/>
      </geometry>
      <material name="">
        <color rgba="0.792156862745098 0.819607843137255 0.933333333333333 1"/>
      </material>
    </visual>
    <collision>
      <origin rpy="0 0 0" xyz="0 0 0"/>
      <geometry>
        <mesh filename="package://iai_boxy_base/meshes/base_link.STL"/>
      </geometry>
    </collision>
  </link>
  <link name="laser_reference_front"/>
  <joint name="laser_reference_front_joint" type="fixed">
    <origin rpy="4.70027852409606E-15 -4.70862925338426E-15 -0.78539816339745" xyz="0.235926406871192 -0.497427516941588 0.157500000000002"/>
    <parent link="base_link"/>
    <child link="laser_reference_front"/>
    <axis xyz="0 0 0"/>
  </joint>
  <link name="laser_reference_back"/>
  <joint name="laser_reference_back_joint" type="fixed">
    <origin rpy="-4.33428293429891E-15 4.09876906549633E-15 2.35619449019234" xyz="-0.738426406871194 0.0504883651003683 0.157499999999995"/>
    <parent link="base_link"/>
    <child link="laser_reference_back"/>
    <axis xyz="0 0 0"/>
  </joint>
  <link name="base_footprint">
	</link>
  <!-- JOINT to define base_footprint -->
  <joint name="base_footprint_joint" type="fixed">
    <origin rpy="0 0 0" xyz="0.36 0.25 0.16"/>
    <parent link="base_footprint"/>
    <child link="base_link"/>
  </joint>
  <!-- /JOINT for base_footprint -->
  <!-- JOINT to connect the base with the pw070 -->
  <joint name="head_joint" type="fixed">
    <origin rpy="0 0 0" xyz="0.2 -0.21 1.48"/>
    <parent link="base_link"/>
    <child link="pw070_base_link"/>
  </joint>
  <!-- /JOINT to connect the base with the pw070 -->
  <link name="pw070_base_link">
    <inertial>
      <origin rpy="0 0 0" xyz="1.00847964366636E-18 9.83435359832521E-19 0.0183994788995853"/>
      <mass value="0.115600516395015"/>
      <inertia ixx="4.22762247390204E-05" ixy="-1.61518323710916E-21" ixz="1.64564610608109E-21" iyy="4.22005265483119E-05" iyz="-1.05221078652886E-21" izz="5.93634422539094E-05"/>
    </inertial>
    <visual>
      <origin rpy="0 0 0" xyz="0 0 0"/>
      <geometry>
        <mesh filename="package://iai_schunk_pw070_v6//meshes/pw070_base_link.STL"/>
      </geometry>
      <material name="">
        <color rgba="0.501960784313725 0.501960784313725 0.250980392156863 1"/>
      </material>
    </visual>
    <collision>
      <origin rpy="0 0 0" xyz="0 0 0"/>
      <geometry>
        <mesh filename="package://iai_schunk_pw070_v6//meshes/pw070_base_link.STL"/>
      </geometry>
    </collision>
  </link>
  <link name="pw070_box">
    <inertial>
      <origin rpy="0 0 0" xyz="0.00797025295401261 9.94149680106761E-19 0.00180349929967392"/>
      <mass value="0.795464859270861"/>
      <inertia ixx="0.00106829634194245" ixy="8.63510385056357E-20" ixz="-1.28767421479418E-05" iyy="0.00158199067955857" iyz="-1.66255748362911E-08" izz="0.00115077124113952"/>
    </inertial>
    <visual>
      <origin rpy="0 0 0" xyz="0 0 0"/>
      <geometry>
        <mesh filename="package://iai_schunk_pw070_v6//meshes/pw070_box.STL"/>
      </geometry>
      <material name="">
        <color rgba="0.501960784313725 0.501960784313725 0.250980392156863 1"/>
      </material>
    </visual>
    <collision>
      <origin rpy="0 0 0" xyz="0 0 0"/>
      <geometry>
        <mesh filename="package://iai_schunk_pw070_v6//meshes/pw070_box.STL"/>
      </geometry>
    </collision>
  </link>
  <joint name="head_pan_joint" type="revolute">
    <origin rpy="3.1416 0 -1.5708" xyz="0 0 0.0938"/>
    <parent link="pw070_base_link"/>
    <child link="pw070_box"/>
    <axis xyz="0 0 1"/>
    <limit effort="0" lower="-1.57" upper="1.57" velocity="0.75"/>
  </joint>
  <transmission name="head_pan_transmission" type="pr2_mechanism_model/SimpleTransmission">
    <actuator name="head_pan_motor"/>
    <joint name="head_pan_joint"/>
    <mechanicalReduction>1.0</mechanicalReduction>
  </transmission>
  <link name="pw070_plate">
    <inertial>
      <origin rpy="0 0 0" xyz="-0.0183186378092207 -8.79591761068821E-18 -0.0206679097089721"/>
      <mass value="0.20324493262428"/>
      <inertia ixx="0.00027991057755713" ixy="4.77643348599192E-08" ixz="-7.69501477424774E-05" iyy="0.000674719224958911" iyz="2.09169636982284E-20" izz="0.000546047259750224"/>
    </inertial>
    <visual>
      <origin rpy="0 0 0" xyz="0 0 0"/>
      <geometry>
        <mesh filename="package://iai_schunk_pw070_v6//meshes/pw070_plate.STL"/>
      </geometry>
      <material name="">
        <color rgba="0.501960784313725 0.501960784313725 0.250980392156863 1"/>
      </material>
    </visual>
    <collision>
      <origin rpy="0 0 0" xyz="0 0 0"/>
      <geometry>
        <mesh filename="package://iai_schunk_pw070_v6//meshes/pw070_plate.STL"/>
      </geometry>
    </collision>
  </link>
  <joint name="head_tilt_joint" type="revolute">
    <origin rpy="0 0 0" xyz="0 0 0"/>
    <parent link="pw070_box"/>
    <child link="pw070_plate"/>
    <axis xyz="1 0 0"/>
    <limit effort="0" lower="-1.3" upper="1.3" velocity="0.8"/>
  </joint>
  <transmission name="head_tilt_transmission" type="pr2_mechanism_model/SimpleTransmission">
    <actuator name="head_tilt_motor"/>
    <joint name="head_tilt_joint"/>
    <mechanicalReduction>1.0</mechanicalReduction>
  </transmission>
  <link name="pw070_frame_out"/>
  <joint name="trans_frame_out" type="fixed">
    <origin rpy="3.1416 0 -1.5708" xyz="0 0 -0.07"/>
    <parent link="pw070_plate"/>
    <child link="pw070_frame_out"/>
    <axis xyz="0 0 0"/>
  </joint>
  <!-- JOINT to place the kinect2 camera on the pw070 -->
  <!-- Comes from tool_H_clink in the calibration
             The quaternion was converted to RPY using python and KDL
              halcon has quat: w x y z
              kdl and tf_static_transform_publisher use: x y z w
            So take the first number from the halcon quat and put it last for KDL.
           import PyKDL as p; r2 = p.Rotation.Quaternion(-0.494547,0.491515,-0.506787,0.506955) ; r2.GetRPY() 
  answer: (-1.5431199762943342, -0.0029080109443817533, -1.5676362600579434) -->
  <joint name="kinect2_joint" type="fixed">
    <origin rpy="-1.5431199762943342 -0.0029080109443817533 -1.5676362600579434" xyz="0.0402529 -0.0959434 0.0332714"/>
    <parent link="pw070_frame_out"/>
    <child link="head_mount_kinect2_rgb_optical_frame"/>
  </joint>
  <!-- JOINT to place the kinect2 camera on the pw070 -->
  <!-- empty link for the rgb_optical_frame -->
  <link name="head_mount_kinect2_rgb_optical_frame">
        </link>
  <!-- JOINT to connect the base with the torso -->
  <joint name="torso_joint" type="fixed">
    <origin rpy="0 0 0" xyz="0 0.065 0.41"/>
    <parent link="base_link"/>
    <child link="torso_base_link"/>
  </joint>
  <!-- /JOINT to connect the base with the torso -->
  <link name="torso_base_link">
    <inertial>
      <origin rpy="0 0 0" xyz="0.0307745199844149 -0.285 0.513294719377322"/>
      <mass value="3.82694041846288"/>
      <inertia ixx="0.573902290642399" ixy="-2.79383327284778E-16" ixz="1.66346332789765E-05" iyy="0.338648611077492" iyz="-1.04080029390922E-16" izz="0.239577094605918"/>
    </inertial>
    <visual>
      <origin rpy="0 0 0" xyz="0 0 0"/>
      <geometry>
        <mesh filename="package://iai_boxy_torso/meshes/torso_base_link.STL"/>
      </geometry>
      <material name="">
        <color rgba="0.792156862745098 0.819607843137255 0.933333333333333 1"/>
      </material>
    </visual>
    <collision>
      <origin rpy="0 0 0" xyz="0 0 0"/>
      <geometry>
        <mesh filename="package://iai_boxy_torso/meshes/torso_base_link.STL"/>
      </geometry>
    </collision>
  </link>
  <link name="triangle_base_link">
    <inertial>
      <origin rpy="0 0 0" xyz="-0.302419226632933 -0.181352787411384 -0.0325004871109191"/>
      <mass value="7.36699467665114"/>
      <inertia ixx="0.145376830313475" ixy="0.00013303151578814" ixz="4.5364480793564E-05" iyy="0.280518816650801" iyz="-0.00910948982082533" izz="0.330070759835274"/>
    </inertial>
    <visual>
      <origin rpy="0 0 0" xyz="0 0 0"/>
      <geometry>
        <mesh filename="package://iai_boxy_torso/meshes/triangle_base_link.STL"/>
      </geometry>
      <material name="">
        <color rgba="0.792156862745098 0.819607843137255 0.933333333333333 1"/>
      </material>
    </visual>
    <collision>
      <origin rpy="0 0 0" xyz="0 0 0"/>
      <geometry>
        <mesh filename="package://iai_boxy_torso/meshes/triangle_base_link.STL"/>
      </geometry>
    </collision>
  </link>
  <joint name="triangle_base_joint" type="prismatic">
    <!-- Values for the old xtion -->
    <!--origin  
      xyz="0.0674958675029617 0.10311858113734 0.915114291670046"
      rpy="4.7298 6.267 1.5685260" /-->
    <!-- Output of the hand/eye calibration baserobot_H_basearm-->
    <origin rpy="4.70695928 6.28217403836 1.56327975371" xyz="0.0786889663592487 0.0986351579738104 0.906352096493862"/>
    <parent link="base_link"/>
    <child link="triangle_base_link"/>
    <axis xyz="0 -1 0"/>
    <limit effort="0" lower="-0.586" upper="0" velocity="0.02"/>
  </joint>
  <transmission name="triangle_base_transmission" type="pr2_mechanism_model/SimpleTransmission">
    <actuator name="triangle_base_motor"/>
    <joint name="triangle_base_joint"/>
    <mechanicalReduction>1.0</mechanicalReduction>
  </transmission>
  <link name="triangle_left_arm_link"/>
  <joint name="triangle_left_arm_joint" type="fixed">
    <origin rpy="2.61799387796333 -1.5707963267949 0" xyz="-0.239507442352261 -0.181209704131733 -0.137000000000002"/>
    <parent link="triangle_base_link"/>
    <child link="triangle_left_arm_link"/>
    <axis xyz="0 0 0"/>
  </joint>
  <link name="triangle_right_arm_link"/>
  <joint name="triangle_right_arm_joint" type="fixed">
    <origin rpy="2.61799387801966 1.5707963267949 0" xyz="-0.365488160465715 -0.181209539931436 -0.137"/>
    <parent link="triangle_base_link"/>
    <child link="triangle_right_arm_link"/>
    <axis xyz="0 0 0"/>
  </joint>
  <joint name="triangle_left_arm_link_left_arm_base_joint" type="fixed">
    <origin rpy="0 0 1.047198" xyz="0 0 0"/>
    <parent link="triangle_left_arm_link"/>
    <child link="calib_left_arm_base_link"/>
  </joint>
  <link name="calib_left_arm_base_link">
    <inertial>
      <mass value="2.0"/>
      <origin rpy="0 0 0" xyz="0 0 0.055"/>
      <inertia ixx="0.00381666666667" ixy="0" ixz="0" iyy="0.0036" iyz="0" izz="0.00381666666667"/>
    </inertial>
    <visual>
      <origin rpy="0 0 0" xyz="0 0 0"/>
      <geometry>
        <mesh filename="package://iai_kuka_lwr4_description/meshes/arm_base.stl"/>
      </geometry>
      <material name="Orange"/>
    </visual>
    <collision>
      <origin rpy="0 0 0" xyz="0 0 0"/>
      <geometry>
        <mesh filename="package://iai_kuka_lwr4_description/meshes/convex/arm_base_convex.stl"/>
      </geometry>
    </collision>
  </link>
  <gazebo reference="calib_left_arm_base_link">
    <material value="kuka-lwr.material"/>
  </gazebo>
  <joint name="left_arm_0_joint" type="revolute">
    <origin rpy="0 0 0" xyz="0 0 0.11"/>
    <axis xyz="0 0 1"/>
    <limit effort="204" lower="-2.96705972839" upper="2.96705972839" velocity="1.91986217719"/>
    <safety_controller k_position="100" k_velocity="2" soft_lower_limit="-2.93215314335" soft_upper_limit="2.93215314335"/>
    <dynamics damping="0.1"/>
    <parent link="calib_left_arm_base_link"/>
    <child link="left_arm_1_link"/>
  </joint>
  <link name="left_arm_1_link">
    <inertial>
      <mass value="2.0"/>
      <origin rpy="0 0 0" xyz="0 0 0.130"/>
      <inertia ixx="0.0136666666667" ixy="0" ixz="0" iyy="0.003" iyz="0" izz="0.0118666666667"/>
    </inertial>
    <visual>
      <origin rpy="0 0 3.14159265359" xyz="0 0 0"/>
      <geometry>
        <mesh filename="package://iai_kuka_lwr4_description/meshes/arm_segment_a.stl"/>
      </geometry>
      <material name="Orange"/>
    </visual>
    <collision>
      <origin rpy="0 0 3.14159265359" xyz="0 0 0"/>
      <geometry>
        <mesh filename="package://iai_kuka_lwr4_description/meshes/convex/arm_segment_a_convex.stl"/>
      </geometry>
    </collision>
  </link>
  <gazebo reference="left_arm_1_link">
    <material value="kuka-lwr.material"/>
  </gazebo>
  <transmission name="left_arm_0_trans" type="pr2_mechanism_model/SimpleTransmission">
    <actuator name="left_arm_0_motor"/>
    <joint name="left_arm_0_joint"/>
    <mechanicalReduction>1.0</mechanicalReduction>
  </transmission>
  <joint name="left_arm_1_joint" type="revolute">
    <origin rpy="0 0 0" xyz="0 0 0.20"/>
    <axis xyz="0 -1 0"/>
    <limit effort="306" lower="-2.09439510239" upper="2.09439510239" velocity="1.91986217719"/>
    <safety_controller k_position="100" k_velocity="2" soft_lower_limit="-2.05948851735" soft_upper_limit="2.05948851735"/>
    <dynamics damping="0.1"/>
    <parent link="left_arm_1_link"/>
    <child link="left_arm_2_link"/>
  </joint>
  <link name="left_arm_2_link">
    <inertial>
      <mass value="2.0"/>
      <origin rpy="0 0 0" xyz="0 0.06 0.07"/>
      <inertia ixx="0.0136666666667" ixy="0" ixz="0" iyy="0.003" iyz="0" izz="0.0118666666667"/>
    </inertial>
    <visual>
      <origin rpy="3.14159265359 0 3.14159265359" xyz="0 0 0.2"/>
      <geometry>
        <mesh filename="package://iai_kuka_lwr4_description/meshes/arm_segment_b.stl"/>
      </geometry>
      <material name="Orange"/>
    </visual>
    <collision>
      <origin rpy="3.14159265359 0 3.14159265359" xyz="0 0 0.2"/>
      <geometry>
        <mesh filename="package://iai_kuka_lwr4_description/meshes/convex/arm_segment_b_convex.stl"/>
      </geometry>
    </collision>
  </link>
  <gazebo reference="left_arm_2_link">
    <material value="kuka-lwr.material"/>
  </gazebo>
  <transmission name="left_arm_1_trans" type="pr2_mechanism_model/SimpleTransmission">
    <actuator name="left_arm_1_motor"/>
    <joint name="left_arm_1_joint"/>
    <mechanicalReduction>1.0</mechanicalReduction>
  </transmission>
  <joint name="left_arm_2_joint" type="revolute">
    <origin rpy="0 0 0" xyz="0 0 0.20"/>
    <axis xyz="0 0 1"/>
    <limit effort="204" lower="-2.96705972839" upper="2.96705972839" velocity="2.26892802759"/>
    <safety_controller k_position="100" k_velocity="2" soft_lower_limit="-2.93215314335" soft_upper_limit="2.93215314335"/>
    <dynamics damping="0.1"/>
    <parent link="left_arm_2_link"/>
    <child link="left_arm_3_link"/>
  </joint>
  <link name="left_arm_3_link">
    <inertial>
      <mass value="2.0"/>
      <origin rpy="0 0 0" xyz="0 0.06 0.130"/>
      <inertia ixx="0.0136666666667" ixy="0" ixz="0" iyy="0.003" iyz="0" izz="0.0118666666667"/>
    </inertial>
    <visual>
      <origin rpy="0 0 0" xyz="0 0 0"/>
      <geometry>
        <mesh filename="package://iai_kuka_lwr4_description/meshes/arm_segment_a.stl"/>
      </geometry>
      <material name="Orange"/>
    </visual>
    <collision>
      <origin rpy="0 0 0" xyz="0 0 0"/>
      <geometry>
        <mesh filename="package://iai_kuka_lwr4_description/meshes/convex/arm_segment_a_convex.stl"/>
      </geometry>
    </collision>
  </link>
  <gazebo reference="left_arm_3_link">
    <material value="kuka-lwr.material"/>
  </gazebo>
  <transmission name="left_arm_2_trans" type="pr2_mechanism_model/SimpleTransmission">
    <actuator name="left_arm_2_motor"/>
    <joint name="left_arm_2_joint"/>
    <mechanicalReduction>1.0</mechanicalReduction>
  </transmission>
  <joint name="left_arm_3_joint" type="revolute">
    <origin rpy="0 0 0" xyz="0 0 0.20"/>
    <axis xyz="0 1 0"/>
    <limit effort="306" lower="-2.09439510239" upper="2.09439510239" velocity="2.26892802759"/>
    <safety_controller k_position="100" k_velocity="2" soft_lower_limit="-2.05948851735" soft_upper_limit="2.05948851735"/>
    <dynamics damping="0.1"/>
    <parent link="left_arm_3_link"/>
    <child link="left_arm_4_link"/>
  </joint>
  <link name="left_arm_4_link">
    <inertial>
      <mass value="2.0"/>
      <origin rpy="0 0 0" xyz="0 -0.06 0.07"/>
      <inertia ixx="0.0136666666667" ixy="0" ixz="0" iyy="0.003" iyz="0" izz="0.0118666666667"/>
    </inertial>
    <visual>
      <origin rpy="0 3.14159265359 3.14159265359" xyz="0 0 0.2"/>
      <geometry>
        <mesh filename="package://iai_kuka_lwr4_description/meshes/arm_segment_b.stl"/>
      </geometry>
      <material name="Orange"/>
    </visual>
    <collision>
      <origin rpy="0 3.14159265359 3.14159265359" xyz="0 0 0.2"/>
      <geometry>
        <mesh filename="package://iai_kuka_lwr4_description/meshes/convex/arm_segment_b_convex.stl"/>
      </geometry>
    </collision>
  </link>
  <gazebo reference="left_arm_4_link">
    <material value="kuka-lwr.material"/>
  </gazebo>
  <transmission name="left_arm_3_trans" type="pr2_mechanism_model/SimpleTransmission">
    <actuator name="left_arm_3_motor"/>
    <joint name="left_arm_3_joint"/>
    <mechanicalReduction>1.0</mechanicalReduction>
  </transmission>
  <joint name="left_arm_4_joint" type="revolute">
    <origin rpy="0 0 0" xyz="0 0 0.20"/>
    <axis xyz="0 0 1"/>
    <limit effort="204" lower="-2.96705972839" upper="2.96705972839" velocity="2.26892802759"/>
    <safety_controller k_position="100" k_velocity="2" soft_lower_limit="-2.93215314335" soft_upper_limit="2.93215314335"/>
    <dynamics damping="0.1"/>
    <parent link="left_arm_4_link"/>
    <child link="left_arm_5_link"/>
  </joint>
  <link name="left_arm_5_link">
    <inertial>
      <mass value="2.0"/>
      <origin rpy="0 0 0" xyz="0 0 0.124"/>
      <inertia ixx="0.0126506666667" ixy="0" ixz="0" iyy="0.003" iyz="0" izz="0.0108506666667"/>
    </inertial>
    <visual>
      <origin rpy="0 0 3.14159265359" xyz="0 0 0"/>
      <geometry name="left_arm_5_geom">
        <mesh filename="package://iai_kuka_lwr4_description/meshes/arm_segment_last.stl"/>
      </geometry>
      <material name="Orange"/>
    </visual>
    <collision>
      <origin rpy="0 0 3.14159265359" xyz="0 0 0"/>
      <geometry>
        <mesh filename="package://iai_kuka_lwr4_description/meshes/convex/arm_segment_last_convex.stl"/>
      </geometry>
    </collision>
  </link>
  <gazebo reference="left_arm_5_link">
    <material value="kuka-lwr.material"/>
  </gazebo>
  <transmission name="left_arm_4_trans" type="pr2_mechanism_model/SimpleTransmission">
    <actuator name="left_arm_4_motor"/>
    <joint name="left_arm_4_joint"/>
    <mechanicalReduction>1.0</mechanicalReduction>
  </transmission>
  <joint name="left_arm_5_joint" type="revolute">
    <origin rpy="0 0 0" xyz="0 0 0.19"/>
    <axis xyz="0 -1 0"/>
    <limit effort="306" lower="-2.09439510239" upper="2.09439510239" velocity="3.14159265359"/>
    <safety_controller k_position="100" k_velocity="2" soft_lower_limit="-2.05948851735" soft_upper_limit="2.05948851735"/>
    <dynamics damping="0.1"/>
    <parent link="left_arm_5_link"/>
    <child link="left_arm_6_link"/>
  </joint>
  <link name="left_arm_6_link">
    <inertial>
      <mass value="2.0"/>
      <origin rpy="0 0 0" xyz="0 0 0.0625"/>
      <inertia ixx="0.00520833333333" ixy="0" ixz="0" iyy="0.00520833333333" iyz="0" izz="0.00520833333333"/>
    </inertial>
    <visual>
      <origin rpy="0 0 3.14159265359" xyz="0 0 0"/>
      <geometry>
        <mesh filename="package://iai_kuka_lwr4_description/meshes/arm_wrist.stl"/>
      </geometry>
      <material name="Grey"/>
    </visual>
    <collision>
      <origin rpy="0 0 3.14159265359" xyz="0 0 0"/>
      <geometry>
        <mesh filename="package://iai_kuka_lwr4_description/meshes/convex/arm_wrist_convex.stl"/>
      </geometry>
    </collision>
  </link>
  <gazebo reference="left_arm_6_link">
    <material value="kuka-lwr.material"/>
  </gazebo>
  <transmission name="left_arm_5_trans" type="pr2_mechanism_model/SimpleTransmission">
    <actuator name="left_arm_5_motor"/>
    <joint name="left_arm_5_joint"/>
    <mechanicalReduction>1.0</mechanicalReduction>
  </transmission>
  <joint name="left_arm_6_joint" type="revolute">
    <origin rpy="0 0 0" xyz="0 0 0"/>
    <axis xyz="0 0 1"/>
    <limit effort="204" lower="-2.96705972839" upper="2.96705972839" velocity="3.14159265359"/>
    <safety_controller k_position="100" k_velocity="2" soft_lower_limit="-2.93215314335" soft_upper_limit="2.93215314335"/>
    <dynamics damping="0.1"/>
    <parent link="left_arm_6_link"/>
    <child link="left_arm_7_link"/>
  </joint>
  <link name="left_arm_7_link">
    <inertial>
      <mass value="2.0"/>
      <origin xyz="0 0 0"/>
      <inertia ixx="0.333333333333" ixy="0" ixz="0" iyy="0.333333333333" iyz="0" izz="0.333333333333"/>
    </inertial>
    <visual>
      <origin rpy="0 0 0" xyz="0 0 0.078"/>
      <geometry>
        <mesh filename="package://iai_kuka_lwr4_description/meshes/arm_flanche.stl"/>
      </geometry>
      <material name="Grey"/>
    </visual>
    <collision>
      <origin rpy="0 0 0" xyz="0 0 0.078"/>
      <geometry>
        <mesh filename="package://iai_kuka_lwr4_description/meshes/convex/arm_flanche_convex.stl"/>
      </geometry>
    </collision>
  </link>
  <gazebo reference="left_arm_7_link">
    <material value="kuka-lwr.material"/>
  </gazebo>
  <transmission name="left_arm_6_trans" type="pr2_mechanism_model/SimpleTransmission">
    <actuator name="left_arm_6_motor"/>
    <joint name="left_arm_6_joint"/>
    <mechanicalReduction>1.0</mechanicalReduction>
  </transmission>
  <joint name="left_arm_flange_joint" type="fixed">
    <origin rpy="0 0 0" xyz="0 0 0.078"/>
    <parent link="left_arm_7_link"/>
    <child link="left_arm_flange_link"/>
  </joint>
  <link name="left_arm_flange_link">
    <inertial>
      <mass value="0.5"/>
      <origin rpy="0 0 0" xyz="0 0 0"/>
      <inertia ixx="0.0833333333333" ixy="0" ixz="0" iyy="0.0833333333333" iyz="0" izz="0.0833333333333"/>
    </inertial>
  </link>
  <!-- Old gripper
	<xacro:include filename="$(find iai_weiss_wsg50)/robots/weiss_wsg50.urdf" />
	
	<joint name="left_hand_joint" type="fixed">
		<origin xyz="0 0 0.08" rpy="0 0 0" />
		<parent link="left_arm_7_link" />
		<child link="gripper_base_link" />
	</joint>
  -->
  <!--This is a 60deg rotation to calib_right_arm_base_link -->
  <joint name="triangle_right_arm_link_right_arm_base_joint" type="fixed">
    <origin rpy="0 0 -1.047198" xyz="0 0 0"/>
    <parent link="triangle_right_arm_link"/>
    <child link="calib_right_arm_base_link"/>
  </joint>
  <link name="calib_right_arm_base_link">
    <inertial>
      <mass value="2.0"/>
      <origin rpy="0 0 0" xyz="0 0 0.055"/>
      <inertia ixx="0.00381666666667" ixy="0" ixz="0" iyy="0.0036" iyz="0" izz="0.00381666666667"/>
    </inertial>
    <visual>
      <origin rpy="0 0 0" xyz="0 0 0"/>
      <geometry>
        <mesh filename="package://iai_kuka_lwr4_description/meshes/arm_base.stl"/>
      </geometry>
      <material name="Orange"/>
    </visual>
    <collision>
      <origin rpy="0 0 0" xyz="0 0 0"/>
      <geometry>
        <mesh filename="package://iai_kuka_lwr4_description/meshes/convex/arm_base_convex.stl"/>
      </geometry>
    </collision>
  </link>
  <gazebo reference="calib_right_arm_base_link">
    <material value="kuka-lwr.material"/>
  </gazebo>
  <joint name="right_arm_0_joint" type="revolute">
    <origin rpy="0 0 0" xyz="0 0 0.11"/>
    <axis xyz="0 0 1"/>
    <limit effort="204" lower="-2.96705972839" upper="2.96705972839" velocity="1.91986217719"/>
    <safety_controller k_position="100" k_velocity="2" soft_lower_limit="-2.93215314335" soft_upper_limit="2.93215314335"/>
    <dynamics damping="0.1"/>
    <parent link="calib_right_arm_base_link"/>
    <child link="right_arm_1_link"/>
  </joint>
  <link name="right_arm_1_link">
    <inertial>
      <mass value="2.0"/>
      <origin rpy="0 0 0" xyz="0 0 0.130"/>
      <inertia ixx="0.0136666666667" ixy="0" ixz="0" iyy="0.003" iyz="0" izz="0.0118666666667"/>
    </inertial>
    <visual>
      <origin rpy="0 0 3.14159265359" xyz="0 0 0"/>
      <geometry>
        <mesh filename="package://iai_kuka_lwr4_description/meshes/arm_segment_a.stl"/>
      </geometry>
      <material name="Orange"/>
    </visual>
    <collision>
      <origin rpy="0 0 3.14159265359" xyz="0 0 0"/>
      <geometry>
        <mesh filename="package://iai_kuka_lwr4_description/meshes/convex/arm_segment_a_convex.stl"/>
      </geometry>
    </collision>
  </link>
  <gazebo reference="right_arm_1_link">
    <material value="kuka-lwr.material"/>
  </gazebo>
  <transmission name="right_arm_0_trans" type="pr2_mechanism_model/SimpleTransmission">
    <actuator name="right_arm_0_motor"/>
    <joint name="right_arm_0_joint"/>
    <mechanicalReduction>1.0</mechanicalReduction>
  </transmission>
  <joint name="right_arm_1_joint" type="revolute">
    <origin rpy="0 0 0" xyz="0 0 0.20"/>
    <axis xyz="0 -1 0"/>
    <limit effort="306" lower="-2.09439510239" upper="2.09439510239" velocity="1.91986217719"/>
    <safety_controller k_position="100" k_velocity="2" soft_lower_limit="-2.05948851735" soft_upper_limit="2.05948851735"/>
    <dynamics damping="0.1"/>
    <parent link="right_arm_1_link"/>
    <child link="right_arm_2_link"/>
  </joint>
  <link name="right_arm_2_link">
    <inertial>
      <mass value="2.0"/>
      <origin rpy="0 0 0" xyz="0 0.06 0.07"/>
      <inertia ixx="0.0136666666667" ixy="0" ixz="0" iyy="0.003" iyz="0" izz="0.0118666666667"/>
    </inertial>
    <visual>
      <origin rpy="3.14159265359 0 3.14159265359" xyz="0 0 0.2"/>
      <geometry>
        <mesh filename="package://iai_kuka_lwr4_description/meshes/arm_segment_b.stl"/>
      </geometry>
      <material name="Orange"/>
    </visual>
    <collision>
      <origin rpy="3.14159265359 0 3.14159265359" xyz="0 0 0.2"/>
      <geometry>
        <mesh filename="package://iai_kuka_lwr4_description/meshes/convex/arm_segment_b_convex.stl"/>
      </geometry>
    </collision>
  </link>
  <gazebo reference="right_arm_2_link">
    <material value="kuka-lwr.material"/>
  </gazebo>
  <transmission name="right_arm_1_trans" type="pr2_mechanism_model/SimpleTransmission">
    <actuator name="right_arm_1_motor"/>
    <joint name="right_arm_1_joint"/>
    <mechanicalReduction>1.0</mechanicalReduction>
  </transmission>
  <joint name="right_arm_2_joint" type="revolute">
    <origin rpy="0 0 0" xyz="0 0 0.20"/>
    <axis xyz="0 0 1"/>
    <limit effort="204" lower="-2.96705972839" upper="2.96705972839" velocity="2.26892802759"/>
    <safety_controller k_position="100" k_velocity="2" soft_lower_limit="-2.93215314335" soft_upper_limit="2.93215314335"/>
    <dynamics damping="0.1"/>
    <parent link="right_arm_2_link"/>
    <child link="right_arm_3_link"/>
  </joint>
  <link name="right_arm_3_link">
    <inertial>
      <mass value="2.0"/>
      <origin rpy="0 0 0" xyz="0 0.06 0.130"/>
      <inertia ixx="0.0136666666667" ixy="0" ixz="0" iyy="0.003" iyz="0" izz="0.0118666666667"/>
    </inertial>
    <visual>
      <origin rpy="0 0 0" xyz="0 0 0"/>
      <geometry>
        <mesh filename="package://iai_kuka_lwr4_description/meshes/arm_segment_a.stl"/>
      </geometry>
      <material name="Orange"/>
    </visual>
    <collision>
      <origin rpy="0 0 0" xyz="0 0 0"/>
      <geometry>
        <mesh filename="package://iai_kuka_lwr4_description/meshes/convex/arm_segment_a_convex.stl"/>
      </geometry>
    </collision>
  </link>
  <gazebo reference="right_arm_3_link">
    <material value="kuka-lwr.material"/>
  </gazebo>
  <transmission name="right_arm_2_trans" type="pr2_mechanism_model/SimpleTransmission">
    <actuator name="right_arm_2_motor"/>
    <joint name="right_arm_2_joint"/>
    <mechanicalReduction>1.0</mechanicalReduction>
  </transmission>
  <joint name="right_arm_3_joint" type="revolute">
    <origin rpy="0 0 0" xyz="0 0 0.20"/>
    <axis xyz="0 1 0"/>
    <limit effort="306" lower="-2.09439510239" upper="2.09439510239" velocity="2.26892802759"/>
    <safety_controller k_position="100" k_velocity="2" soft_lower_limit="-2.05948851735" soft_upper_limit="2.05948851735"/>
    <dynamics damping="0.1"/>
    <parent link="right_arm_3_link"/>
    <child link="right_arm_4_link"/>
  </joint>
  <link name="right_arm_4_link">
    <inertial>
      <mass value="2.0"/>
      <origin rpy="0 0 0" xyz="0 -0.06 0.07"/>
      <inertia ixx="0.0136666666667" ixy="0" ixz="0" iyy="0.003" iyz="0" izz="0.0118666666667"/>
    </inertial>
    <visual>
      <origin rpy="0 3.14159265359 3.14159265359" xyz="0 0 0.2"/>
      <geometry>
        <mesh filename="package://iai_kuka_lwr4_description/meshes/arm_segment_b.stl"/>
      </geometry>
      <material name="Orange"/>
    </visual>
    <collision>
      <origin rpy="0 3.14159265359 3.14159265359" xyz="0 0 0.2"/>
      <geometry>
        <mesh filename="package://iai_kuka_lwr4_description/meshes/convex/arm_segment_b_convex.stl"/>
      </geometry>
    </collision>
  </link>
  <gazebo reference="right_arm_4_link">
    <material value="kuka-lwr.material"/>
  </gazebo>
  <transmission name="right_arm_3_trans" type="pr2_mechanism_model/SimpleTransmission">
    <actuator name="right_arm_3_motor"/>
    <joint name="right_arm_3_joint"/>
    <mechanicalReduction>1.0</mechanicalReduction>
  </transmission>
  <joint name="right_arm_4_joint" type="revolute">
    <origin rpy="0 0 0" xyz="0 0 0.20"/>
    <axis xyz="0 0 1"/>
    <limit effort="204" lower="-2.96705972839" upper="2.96705972839" velocity="2.26892802759"/>
    <safety_controller k_position="100" k_velocity="2" soft_lower_limit="-2.93215314335" soft_upper_limit="2.93215314335"/>
    <dynamics damping="0.1"/>
    <parent link="right_arm_4_link"/>
    <child link="right_arm_5_link"/>
  </joint>
  <link name="right_arm_5_link">
    <inertial>
      <mass value="2.0"/>
      <origin rpy="0 0 0" xyz="0 0 0.124"/>
      <inertia ixx="0.0126506666667" ixy="0" ixz="0" iyy="0.003" iyz="0" izz="0.0108506666667"/>
    </inertial>
    <visual>
      <origin rpy="0 0 3.14159265359" xyz="0 0 0"/>
      <geometry name="right_arm_5_geom">
        <mesh filename="package://iai_kuka_lwr4_description/meshes/arm_segment_last.stl"/>
      </geometry>
      <material name="Orange"/>
    </visual>
    <collision>
      <origin rpy="0 0 3.14159265359" xyz="0 0 0"/>
      <geometry>
        <mesh filename="package://iai_kuka_lwr4_description/meshes/convex/arm_segment_last_convex.stl"/>
      </geometry>
    </collision>
  </link>
  <gazebo reference="right_arm_5_link">
    <material value="kuka-lwr.material"/>
  </gazebo>
  <transmission name="right_arm_4_trans" type="pr2_mechanism_model/SimpleTransmission">
    <actuator name="right_arm_4_motor"/>
    <joint name="right_arm_4_joint"/>
    <mechanicalReduction>1.0</mechanicalReduction>
  </transmission>
  <joint name="right_arm_5_joint" type="revolute">
    <origin rpy="0 0 0" xyz="0 0 0.19"/>
    <axis xyz="0 -1 0"/>
    <limit effort="306" lower="-2.09439510239" upper="2.09439510239" velocity="3.14159265359"/>
    <safety_controller k_position="100" k_velocity="2" soft_lower_limit="-2.05948851735" soft_upper_limit="2.05948851735"/>
    <dynamics damping="0.1"/>
    <parent link="right_arm_5_link"/>
    <child link="right_arm_6_link"/>
  </joint>
  <link name="right_arm_6_link">
    <inertial>
      <mass value="2.0"/>
      <origin rpy="0 0 0" xyz="0 0 0.0625"/>
      <inertia ixx="0.00520833333333" ixy="0" ixz="0" iyy="0.00520833333333" iyz="0" izz="0.00520833333333"/>
    </inertial>
    <visual>
      <origin rpy="0 0 3.14159265359" xyz="0 0 0"/>
      <geometry>
        <mesh filename="package://iai_kuka_lwr4_description/meshes/arm_wrist.stl"/>
      </geometry>
      <material name="Grey"/>
    </visual>
    <collision>
      <origin rpy="0 0 3.14159265359" xyz="0 0 0"/>
      <geometry>
        <mesh filename="package://iai_kuka_lwr4_description/meshes/convex/arm_wrist_convex.stl"/>
      </geometry>
    </collision>
  </link>
  <gazebo reference="right_arm_6_link">
    <material value="kuka-lwr.material"/>
  </gazebo>
  <transmission name="right_arm_5_trans" type="pr2_mechanism_model/SimpleTransmission">
    <actuator name="right_arm_5_motor"/>
    <joint name="right_arm_5_joint"/>
    <mechanicalReduction>1.0</mechanicalReduction>
  </transmission>
  <joint name="right_arm_6_joint" type="revolute">
    <origin rpy="0 0 0" xyz="0 0 0"/>
    <axis xyz="0 0 1"/>
    <limit effort="204" lower="-2.96705972839" upper="2.96705972839" velocity="3.14159265359"/>
    <safety_controller k_position="100" k_velocity="2" soft_lower_limit="-2.93215314335" soft_upper_limit="2.93215314335"/>
    <dynamics damping="0.1"/>
    <parent link="right_arm_6_link"/>
    <child link="right_arm_7_link"/>
  </joint>
  <link name="right_arm_7_link">
    <inertial>
      <mass value="2.0"/>
      <origin xyz="0 0 0"/>
      <inertia ixx="0.333333333333" ixy="0" ixz="0" iyy="0.333333333333" iyz="0" izz="0.333333333333"/>
    </inertial>
    <visual>
      <origin rpy="0 0 0" xyz="0 0 0.078"/>
      <geometry>
        <mesh filename="package://iai_kuka_lwr4_description/meshes/arm_flanche.stl"/>
      </geometry>
      <material name="Grey"/>
    </visual>
    <collision>
      <origin rpy="0 0 0" xyz="0 0 0.078"/>
      <geometry>
        <mesh filename="package://iai_kuka_lwr4_description/meshes/convex/arm_flanche_convex.stl"/>
      </geometry>
    </collision>
  </link>
  <gazebo reference="right_arm_7_link">
    <material value="kuka-lwr.material"/>
  </gazebo>
  <transmission name="right_arm_6_trans" type="pr2_mechanism_model/SimpleTransmission">
    <actuator name="right_arm_6_motor"/>
    <joint name="right_arm_6_joint"/>
    <mechanicalReduction>1.0</mechanicalReduction>
  </transmission>
  <joint name="right_arm_flange_joint" type="fixed">
    <origin rpy="0 0 0" xyz="0 0 0.078"/>
    <parent link="right_arm_7_link"/>
    <child link="right_arm_flange_link"/>
  </joint>
  <link name="right_arm_flange_link">
    <inertial>
      <mass value="0.5"/>
      <origin rpy="0 0 0" xyz="0 0 0"/>
      <inertia ixx="0.0833333333333" ixy="0" ixz="0" iyy="0.0833333333333" iyz="0" izz="0.0833333333333"/>
    </inertial>
  </link>
  <joint name="left_gripper_anterior_gripper_joint" type="fixed">
    <origin rpy="0 0 0" xyz="0 0 0"/>
    <parent link="left_arm_flange_link"/>
    <child link="left_gripper_base_link"/>
  </joint>
  <link name="left_gripper_base_link">
    <inertial>
      <mass value="0.25"/>
      <origin xyz="0 0 0"/>
      <!--inertia ixx="1.0" ixy="0.0" ixz="0.0"
               iyy="100.0" iyz="0.0" 
               izz="1.0" /-->
      <inertia ixx="1.0" ixy="0.0" ixz="0.0" iyy="1.0" iyz="0.0" izz="1.0"/>
    </inertial>
    <visual>
      <origin rpy="0 0 0" xyz="0.0 0 0"/>
      <geometry>
        <mesh filename="package://iai_wsg_50_description/meshes/WSG50_110.stl" scale="1 1 1"/>
        <!--box size="0.146 0.05 0.0735"/-->
      </geometry>
      <material name="grey">
        <color rgba="0.5 0.5 0.5 1"/>
      </material>
    </visual>
    <collision>
      <origin rpy="0 0 0" xyz="0.0 0 0"/>
      <geometry>
        <!--box size="0.146 0.05 0.0735"/-->
        <mesh filename="package://iai_wsg_50_description/meshes/WSG50_110.stl" scale="1 1 1"/>
      </geometry>
    </collision>
  </link>
  <gazebo reference="left_gripper_base_link">
    <material>Gazebo/Grey</material>
    <turnGravityOff>false</turnGravityOff>
  </gazebo>
  <joint name="left_gripper_base_gripper_left_joint" type="prismatic">
    <limit effort="1.0" lower="-0.055" upper="-0.0027" velocity="0.42"/>
    <origin rpy="0 0 0" xyz="0 0 0"/>
    <!--origin xyz="-0.0067 0 0.049" rpy="0 0 0" /-->
    <parent link="left_gripper_base_link"/>
    <child link="left_gripper_gripper_left_link"/>
    <dynamics damping="100" friction="100"/>
    <axis xyz="1 0 0"/>
    <!-- <limit effort="100" velocity="100"/> -->
  </joint>
  <transmission name="left_gripper_base_trans_left" type="pr2_mechanism_model/SimpleTransmission">
    <actuator name="left_gripper_base_motor_left"/>
    <joint name="left_gripper_base_gripper_left_joint"/>
    <mechanicalReduction>1</mechanicalReduction>
    <motorTorqueConstant>1</motorTorqueConstant>
  </transmission>
  <link name="left_gripper_gripper_left_link">
    <inertial>
      <mass value="0.1"/>
      <origin xyz="0 0 0"/>
      <inertia ixx="1.0" ixy="0.0" ixz="0.0" iyy="1.0" iyz="0.0" izz="1.0"/>
    </inertial>
    <visual>
      <origin rpy="0 0 0" xyz="0.0 0 0"/>
      <geometry>
        <mesh filename="package://iai_wsg_50_description/meshes/GUIDE_WSG50_110.stl" scale="0.001 0.001 0.001"/>
        <!--box size="0.0175 0.03 0.024"/-->
      </geometry>
      <material name="black">
        <color rgba="0 0 0 1"/>
      </material>
    </visual>
    <collision>
      <origin rpy="0 0 0" xyz="0 0 0"/>
      <geometry>
        <!--box size="0.0175 0.03 0.024"/-->
        <mesh filename="package://iai_wsg_50_description/meshes/GUIDE_WSG50_110.stl" scale="0.001 0.001 0.001"/>
      </geometry>
    </collision>
    <contact_coefficients kd="1.0" kp="1000.0" mu="0"/>
  </link>
  <gazebo reference="left_gripper_gripper_left_link">
    <material>Gazebo/Blue</material>
    <turnGravityOff>false</turnGravityOff>
  </gazebo>
  <joint name="left_gripper_guide_joint_finger_left" type="fixed">
    <origin rpy="0 0 0" xyz="0 0 0.023"/>
    <parent link="left_gripper_gripper_left_link"/>
    <child link="left_gripper_finger_left_link"/>
    <dynamics damping="100" friction="100"/>
    <axis xyz="1 0 0"/>
    <!-- <limit effort="100" velocity="100"/> -->
  </joint>
  <link name="left_gripper_finger_left_link">
    <inertial>
      <mass value="0.1"/>
      <origin xyz="0 0 0"/>
      <inertia ixx="1.0" ixy="0.0" ixz="0.0" iyy="1.0" iyz="0.0" izz="1.0"/>
    </inertial>
    <visual>
      <origin rpy="0 0 0" xyz="0.0 0 0"/>
      <geometry>
        <mesh filename="package://iai_wsg_50_description/meshes/WSG-FMF.stl" scale="0.001 0.001 0.001"/>
      </geometry>
      <material name="black">
        <color rgba="0 0 0 1"/>
      </material>
    </visual>
    <collision>
      <origin rpy="0 0 0" xyz="0 0 0"/>
      <geometry>
        <mesh filename="package://iai_wsg_50_description/meshes/WSG-FMF.stl" scale="0.001 0.001 0.001"/>
      </geometry>
    </collision>
    <contact_coefficients kd="1.0" kp="1000.0" mu="0"/>
  </link>
  <gazebo reference="left_gripper_finger_left">
    <material>Gazebo/Blue</material>
    <turnGravityOff>false</turnGravityOff>
  </gazebo>
  <joint name="left_gripper_base_gripper_right_joint" type="prismatic">
    <limit effort="1.0" lower="0.0027" upper="0.055" velocity="0.42"/>
    <origin rpy="0 0 3.14159" xyz="0 0 0"/>
    <parent link="left_gripper_base_link"/>
    <child link="left_gripper_gripper_right_link"/>
    <axis xyz="-1 0 0"/>
    <dynamics damping="100" friction="100"/>
    <!-- <limit effort="100" velocity="100"/>-->
  </joint>
  <transmission name="left_gripper_base_trans_right" type="pr2_mechanism_model/SimpleTransmission">
    <actuator name="left_gripper_base_motor_right"/>
    <joint name="left_gripper_base_gripper_right_joint"/>
    <mechanicalReduction>1</mechanicalReduction>
    <motorTorqueConstant>1</motorTorqueConstant>
  </transmission>
  <link name="left_gripper_gripper_right_link">
    <inertial>
      <mass value="0.1"/>
      <origin xyz="0 0 0"/>
      <inertia ixx="1.0" ixy="0.0" ixz="0.0" iyy="1.0" iyz="0.0" izz="1.0"/>
    </inertial>
    <visual>
      <origin rpy="0 0 0" xyz="0.0 0 0"/>
      <geometry>
        <mesh filename="package://iai_wsg_50_description/meshes/GUIDE_WSG50_110.stl" scale="0.001 0.001 0.001"/>
        <!--box size="0.0175 0.03 0.024"/-->
      </geometry>
      <material name="black">
        <color rgba="0 0 0 1"/>
      </material>
    </visual>
    <collision>
      <origin rpy="0 0 0" xyz="0 0 0"/>
      <geometry>
        <!--box size="0.0175 0.03 0.024"/-->
        <mesh filename="package://iai_wsg_50_description/meshes/GUIDE_WSG50_110.stl" scale="0.001 0.001 0.001"/>
      </geometry>
    </collision>
    <contact_coefficients kd="1.0" kp="1000.0" mu="0"/>
  </link>
  <gazebo reference="gripper_right">
    <material>Gazebo/White</material>
    <turnGravityOff>false</turnGravityOff>
  </gazebo>
  <joint name="left_gripper_guide_joint_finger_right" type="fixed">
    <origin rpy="0 0 0" xyz="0 0 0.023"/>
    <parent link="left_gripper_gripper_right_link"/>
    <child link="left_gripper_finger_right_link"/>
    <dynamics damping="100" friction="100"/>
    <axis xyz="1 0 0"/>
    <limit effort="100" velocity="100"/>
  </joint>
  <link name="left_gripper_finger_right_link">
    <inertial>
      <mass value="0.1"/>
      <origin xyz="0 0 0"/>
      <inertia ixx="1.0" ixy="0.0" ixz="0.0" iyy="1.0" iyz="0.0" izz="1.0"/>
    </inertial>
    <visual>
      <origin rpy="0 0 0" xyz="0.0 0 0"/>
      <geometry>
        <mesh filename="package://iai_wsg_50_description/meshes/WSG-FMF.stl" scale="0.001 0.001 0.001"/>
      </geometry>
      <material name="black">
        <color rgba="0 0 0 1"/>
      </material>
    </visual>
    <collision>
      <origin rpy="0 0 0" xyz="0 0 0"/>
      <geometry>
        <mesh filename="package://iai_wsg_50_description/meshes/WSG-FMF.stl" scale="0.001 0.001 0.001"/>
      </geometry>
    </collision>
    <contact_coefficients kd="1.0" kp="1000.0" mu="0"/>
  </link>
  <gazebo reference="left_gripper_finger_right">
    <material>Gazebo/White</material>
    <turnGravityOff>false</turnGravityOff>
  </gazebo>
  <joint name="right_gripper_anterior_gripper_joint" type="fixed">
    <origin rpy="0 0 0" xyz="0 0 0"/>
    <parent link="right_arm_flange_link"/>
    <child link="right_gripper_base_link"/>
  </joint>
  <link name="right_gripper_base_link">
    <inertial>
      <mass value="0.25"/>
      <origin xyz="0 0 0"/>
      <!--inertia ixx="1.0" ixy="0.0" ixz="0.0"
               iyy="100.0" iyz="0.0" 
               izz="1.0" /-->
      <inertia ixx="1.0" ixy="0.0" ixz="0.0" iyy="1.0" iyz="0.0" izz="1.0"/>
    </inertial>
    <visual>
      <origin rpy="0 0 0" xyz="0.0 0 0"/>
      <geometry>
        <mesh filename="package://iai_wsg_50_description/meshes/WSG50_110.stl" scale="1 1 1"/>
        <!--box size="0.146 0.05 0.0735"/-->
      </geometry>
      <material name="grey">
        <color rgba="0.5 0.5 0.5 1"/>
      </material>
    </visual>
    <collision>
      <origin rpy="0 0 0" xyz="0.0 0 0"/>
      <geometry>
        <!--box size="0.146 0.05 0.0735"/-->
        <mesh filename="package://iai_wsg_50_description/meshes/WSG50_110.stl" scale="1 1 1"/>
      </geometry>
    </collision>
  </link>
  <gazebo reference="right_gripper_base_link">
    <material>Gazebo/Grey</material>
    <turnGravityOff>false</turnGravityOff>
  </gazebo>
  <joint name="right_gripper_base_gripper_left_joint" type="prismatic">
    <limit effort="1.0" lower="-0.055" upper="-0.0027" velocity="0.42"/>
    <origin rpy="0 0 0" xyz="0 0 0"/>
    <!--origin xyz="-0.0067 0 0.049" rpy="0 0 0" /-->
    <parent link="right_gripper_base_link"/>
    <child link="right_gripper_gripper_left_link"/>
    <dynamics damping="100" friction="100"/>
    <axis xyz="1 0 0"/>
    <!-- <limit effort="100" velocity="100"/> -->
  </joint>
  <transmission name="right_gripper_base_trans_left" type="pr2_mechanism_model/SimpleTransmission">
    <actuator name="right_gripper_base_motor_left"/>
    <joint name="right_gripper_base_gripper_left_joint"/>
    <mechanicalReduction>1</mechanicalReduction>
    <motorTorqueConstant>1</motorTorqueConstant>
  </transmission>
  <link name="right_gripper_gripper_left_link">
    <inertial>
      <mass value="0.1"/>
      <origin xyz="0 0 0"/>
      <inertia ixx="1.0" ixy="0.0" ixz="0.0" iyy="1.0" iyz="0.0" izz="1.0"/>
    </inertial>
    <visual>
      <origin rpy="0 0 0" xyz="0.0 0 0"/>
      <geometry>
        <mesh filename="package://iai_wsg_50_description/meshes/GUIDE_WSG50_110.stl" scale="0.001 0.001 0.001"/>
        <!--box size="0.0175 0.03 0.024"/-->
      </geometry>
      <material name="black">
        <color rgba="0 0 0 1"/>
      </material>
    </visual>
    <collision>
      <origin rpy="0 0 0" xyz="0 0 0"/>
      <geometry>
        <!--box size="0.0175 0.03 0.024"/-->
        <mesh filename="package://iai_wsg_50_description/meshes/GUIDE_WSG50_110.stl" scale="0.001 0.001 0.001"/>
      </geometry>
    </collision>
    <contact_coefficients kd="1.0" kp="1000.0" mu="0"/>
  </link>
  <gazebo reference="right_gripper_gripper_left_link">
    <material>Gazebo/Blue</material>
    <turnGravityOff>false</turnGravityOff>
  </gazebo>
  <joint name="right_gripper_guide_joint_finger_left" type="fixed">
    <origin rpy="0 0 0" xyz="0 0 0.023"/>
    <parent link="right_gripper_gripper_left_link"/>
    <child link="right_gripper_finger_left_link"/>
    <dynamics damping="100" friction="100"/>
    <axis xyz="1 0 0"/>
    <!-- <limit effort="100" velocity="100"/> -->
  </joint>
  <link name="right_gripper_finger_left_link">
    <inertial>
      <mass value="0.1"/>
      <origin xyz="0 0 0"/>
      <inertia ixx="1.0" ixy="0.0" ixz="0.0" iyy="1.0" iyz="0.0" izz="1.0"/>
    </inertial>
    <visual>
      <origin rpy="0 0 0" xyz="0.0 0 0"/>
      <geometry>
        <mesh filename="package://iai_wsg_50_description/meshes/WSG-FMF.stl" scale="0.001 0.001 0.001"/>
      </geometry>
      <material name="black">
        <color rgba="0 0 0 1"/>
      </material>
    </visual>
    <collision>
      <origin rpy="0 0 0" xyz="0 0 0"/>
      <geometry>
        <mesh filename="package://iai_wsg_50_description/meshes/WSG-FMF.stl" scale="0.001 0.001 0.001"/>
      </geometry>
    </collision>
    <contact_coefficients kd="1.0" kp="1000.0" mu="0"/>
  </link>
  <gazebo reference="right_gripper_finger_left">
    <material>Gazebo/Blue</material>
    <turnGravityOff>false</turnGravityOff>
  </gazebo>
  <joint name="right_gripper_base_gripper_right_joint" type="prismatic">
    <limit effort="1.0" lower="0.0027" upper="0.055" velocity="0.42"/>
    <origin rpy="0 0 3.14159" xyz="0 0 0"/>
    <parent link="right_gripper_base_link"/>
    <child link="right_gripper_gripper_right_link"/>
    <axis xyz="-1 0 0"/>
    <dynamics damping="100" friction="100"/>
    <!-- <limit effort="100" velocity="100"/>-->
  </joint>
  <transmission name="right_gripper_base_trans_right" type="pr2_mechanism_model/SimpleTransmission">
    <actuator name="right_gripper_base_motor_right"/>
    <joint name="right_gripper_base_gripper_right_joint"/>
    <mechanicalReduction>1</mechanicalReduction>
    <motorTorqueConstant>1</motorTorqueConstant>
  </transmission>
  <link name="right_gripper_gripper_right_link">
    <inertial>
      <mass value="0.1"/>
      <origin xyz="0 0 0"/>
      <inertia ixx="1.0" ixy="0.0" ixz="0.0" iyy="1.0" iyz="0.0" izz="1.0"/>
    </inertial>
    <visual>
      <origin rpy="0 0 0" xyz="0.0 0 0"/>
      <geometry>
        <mesh filename="package://iai_wsg_50_description/meshes/GUIDE_WSG50_110.stl" scale="0.001 0.001 0.001"/>
        <!--box size="0.0175 0.03 0.024"/-->
      </geometry>
      <material name="black">
        <color rgba="0 0 0 1"/>
      </material>
    </visual>
    <collision>
      <origin rpy="0 0 0" xyz="0 0 0"/>
      <geometry>
        <!--box size="0.0175 0.03 0.024"/-->
        <mesh filename="package://iai_wsg_50_description/meshes/GUIDE_WSG50_110.stl" scale="0.001 0.001 0.001"/>
      </geometry>
    </collision>
    <contact_coefficients kd="1.0" kp="1000.0" mu="0"/>
  </link>
  <gazebo reference="gripper_right">
    <material>Gazebo/White</material>
    <turnGravityOff>false</turnGravityOff>
  </gazebo>
  <joint name="right_gripper_guide_joint_finger_right" type="fixed">
    <origin rpy="0 0 0" xyz="0 0 0.023"/>
    <parent link="right_gripper_gripper_right_link"/>
    <child link="right_gripper_finger_right_link"/>
    <dynamics damping="100" friction="100"/>
    <axis xyz="1 0 0"/>
    <limit effort="100" velocity="100"/>
  </joint>
  <link name="right_gripper_finger_right_link">
    <inertial>
      <mass value="0.1"/>
      <origin xyz="0 0 0"/>
      <inertia ixx="1.0" ixy="0.0" ixz="0.0" iyy="1.0" iyz="0.0" izz="1.0"/>
    </inertial>
    <visual>
      <origin rpy="0 0 0" xyz="0.0 0 0"/>
      <geometry>
        <mesh filename="package://iai_wsg_50_description/meshes/WSG-FMF.stl" scale="0.001 0.001 0.001"/>
      </geometry>
      <material name="black">
        <color rgba="0 0 0 1"/>
      </material>
    </visual>
    <collision>
      <origin rpy="0 0 0" xyz="0 0 0"/>
      <geometry>
        <mesh filename="package://iai_wsg_50_description/meshes/WSG-FMF.stl" scale="0.001 0.001 0.001"/>
      </geometry>
    </collision>
    <contact_coefficients kd="1.0" kp="1000.0" mu="0"/>
  </link>
  <gazebo reference="right_gripper_finger_right">
    <material>Gazebo/White</material>
    <turnGravityOff>false</turnGravityOff>
  </gazebo>
</robot>

